Workbook
Name _6__123Graph_AGRAFICO_3: #REF!
Name _14__123Graph_E__200__BPF: #REF!
Name _Regression_Y: #REF!
Name _10__123Graph_BGRAFICO_2: #REF!
Name __123Graph_E: #REF!
Name _21__123Graph_XGRANULOMETRIA_1: #REF!
Name _2__123Graph_A__200__D50: #REF!
Name Z_5465C980_2BDD_11D3_B53D_00500477B0E4_.wvu.PrintTitles: #REF!
Name _24__123Graph_XGRAFICO_1: #REF!
Name _Parse_Out: #REF!
Name _1__123Graph_A__200__BPF: #REF!
Name _13__123Graph_D__200__D50: #REF!
Name _Fill: #REF!
Name _18__123Graph_X__200__BPF: #REF!
Name _14__123Graph_CGRAFICO_2: #REF!
Name __123Graph_BCOSTO: #REF!
Name _Sort: #REF!
Name _Regression_Out: #REF!
Name __123Graph_B: #REF!
Name _4__123Graph_AGRANULOMETRIA_1: #REF!
Name _Table2_Out: #REF!
Name _5__123Graph_AGRAFICO_2: #REF!
Name _11__123Graph_CGRANULOMETRIA_1: #REF!
Name _Key2: #REF!
Name _10__123Graph_C__200__D50: #REF!
Name _Table2_In1: #REF!
Name _6__123Graph_B__200__D50: #REF!
Name __123Graph_ACOSTO: #REF!
Name __123Graph_F: #REF!
Name _5__123Graph_B__200__BPF: #REF!
Name __123Graph_X: #REF!
Name _7__123Graph_BEFICIENCIA_1: #REF!
Name _Parse_In: #REF!
Name __123Graph_A: #REF!
Name __123Graph_C: #REF!
Name _Table1_Out: #REF!
Name _16__123Graph_F__200__BPF: #REF!
Name _19__123Graph_X__200__D50: #REF!
Name _Key1: #REF!
Name _20__123Graph_XEFICIENCIA_1: #REF!
Name _9__123Graph_C__200__BPF: #REF!
Name _12__123Graph_D__200__BPF: #REF!
Name _Regression_X: #REF!
Name _26__123Graph_XGRAFICO_3: #REF!
Name _15__123Graph_E__200__D50: #REF!
Name _25__123Graph_XGRAFICO_2: #REF!
Name _17__123Graph_F__200__D50: #REF!
Name _3__123Graph_AEFICIENCIA_1: #REF!
Name __123Graph_BNONMAN: #REF!
Name RO: #REF!
Name _Table2_In2: #REF!
Name _8__123Graph_BGRANULOMETRIA_1: #REF!
Name Z_5465C980_2BDD_11D3_B53D_00500477B0E4_.wvu.PrintArea: #REF!
Name _Table1_In1: #REF!
Name _4__123Graph_AGRAFICO_1: #REF!
Name __123Graph_D: #REF!
Name Z_E33F0BD9_DDCD_4386_BD14_7DE2581550C6_.wvu.PrintTitles: #REF!

Sheet TEC-02
B2: CORPORACION NACIONAL DEL COBRE DE CHILE
B4: FORMULARIO TEC-02
B5: NÓMINA Y ANTECEDENTES DEL PERSONAL CLAVE
C9: Razón Social del Proponente
C11: Representante Legal | V11: Fecha | W11: 45754
B13: NÓMINA Y ANTECEDENTES DEL PERSONAL CLAVE
B15: Nº | C15: NOMBRE COMPLETO | J15: CARGO A DESEMPEÑAR | O15: TÍTULO PROFESIONAL | T15: AÑOS DE EXPERIENCIA
T16: A | V16: B | X16: C | Z16: D
C36: ='Hoja 1'!A21 | J36: ='Hoja 1'!R21 | O36: ='Hoja 1'!F21 | T36: ='Hoja 1'!N21 | V36: ='Hoja 1'!O21 | X36: ='Hoja 1'!P21 | Z36: ='Hoja 1'!Q21
C37: ='Hoja 1'!A22 | J37: ='Hoja 1'!R22 | O37: ='Hoja 1'!F22 | T37: ='Hoja 1'!N22 | V37: ='Hoja 1'!O22 | X37: ='Hoja 1'!P22 | Z37: ='Hoja 1'!Q22
C38: ='Hoja 1'!A23 | J38: ='Hoja 1'!R23 | O38: ='Hoja 1'!F23 | T38: ='Hoja 1'!N23 | V38: ='Hoja 1'!O23 | X38: ='Hoja 1'!P23 | Z38: ='Hoja 1'!Q23
C39: ='Hoja 1'!A24 | J39: ='Hoja 1'!R24 | O39: ='Hoja 1'!F24 | T39: ='Hoja 1'!N24 | V39: ='Hoja 1'!O24 | X39: ='Hoja 1'!P24 | Z39: ='Hoja 1'!Q24
C40: ='Hoja 1'!A25 | J40: ='Hoja 1'!R25 | O40: ='Hoja 1'!F25 | T40: ='Hoja 1'!N25 | V40: ='Hoja 1'!O25 | X40: ='Hoja 1'!P25 | Z40: ='Hoja 1'!Q25
C41: ='Hoja 1'!A26 | J41: ='Hoja 1'!R26 | O41: ='Hoja 1'!F26 | T41: ='Hoja 1'!N26 | V41: ='Hoja 1'!O26 | X41: ='Hoja 1'!P26 | Z41: ='Hoja 1'!Q26
C42: ='Hoja 1'!A27 | J42: ='Hoja 1'!R27 | O42: ='Hoja 1'!F27 | T42: ='Hoja 1'!N27 | V42: ='Hoja 1'!O27 | X42: ='Hoja 1'!P27 | Z42: ='Hoja 1'!Q27
C43: ='Hoja 1'!A28 | J43: ='Hoja 1'!R28 | O43: ='Hoja 1'!F28 | T43: ='Hoja 1'!N28 | V43: ='Hoja 1'!O28 | X43: ='Hoja 1'!P28 | Z43: ='Hoja 1'!Q28
C44: ='Hoja 1'!A29 | J44: ='Hoja 1'!R29 | O44: ='Hoja 1'!F29 | T44: ='Hoja 1'!N29 | V44: ='Hoja 1'!O29 | X44: ='Hoja 1'!P29 | Z44: ='Hoja 1'!Q29
C45: ='Hoja 1'!A30 | J45: ='Hoja 1'!R30 | O45: ='Hoja 1'!F30 | T45: ='Hoja 1'!N30 | V45: ='Hoja 1'!O30 | X45: ='Hoja 1'!P30 | Z45: ='Hoja 1'!Q30
C46: ='Hoja 1'!A31 | J46: ='Hoja 1'!R31 | O46: ='Hoja 1'!F31 | T46: ='Hoja 1'!N31 | V46: ='Hoja 1'!O31 | X46: ='Hoja 1'!P31 | Z46: ='Hoja 1'!Q31
C47: ='Hoja 1'!A32 | J47: ='Hoja 1'!R32 | O47: ='Hoja 1'!F32 | T47: ='Hoja 1'!N32 | V47: ='Hoja 1'!O32 | X47: ='Hoja 1'!P32 | Z47: ='Hoja 1'!Q32
... C1000: ='Hoja 1'!A985 | J1000: ='Hoja 1'!R985 | O1000: ='Hoja 1'!F985 | T1000: ='Hoja 1'!N985 | V1000: ='Hoja 1'!O985 | X1000: ='Hoja 1'!P985 | Z1000: ='Hoja 1'!Q985

Sheet NOTAS Y EVALUACIONES
A1: NOMBRE COMPLETO | B1: CARGO A DESEMPEÑAR | C1: EVALUACION GENERAL | D1: NOTA | E1: conocimientos especificos | F1: otras experiencias
A2: ='Hoja 1'!A2 -> Isaí Jara Maldonado | B2: ='Hoja 1'!R2 -> Ingeniero de Proyectos SPCI | C2: ='Hoja 1'!M2 -> El candidato presenta un perfil profesional muy adecuado para el cargo, con sólida formación académica y experiencia directa en gestión de proyectos SPCI. Su dominio de herramientas como Power BI y Microsoft Office complementan sus habilidades técnicas. La progresión en su carrera muestra un claro avance hacia roles más complejos y de liderazgo. El CV es claro y completo, lo que facilita la evaluación precisa de su idoneidad. | D2: ='Hoja 1'!S2 -> 6.5 | E2: ='Hoja 1'!U2 | F2: ='Hoja 1'!V2 -> Ha desarrollado funciones complementarias como representante comercial y supervisor de servicios, donde gestionó relaciones con clientes, elaboró informes de rendimiento y organizó equipos de trabajo, habilidades que fortalecen su capacidad de comunicación, organización y atención a la calidad del servicio.
A3: ='Hoja 1'!A3 -> Ángelo Ignacio Pérez Arancibia | B3: ='Hoja 1'!R3 -> Técnico líder en sistemas de protección contra incendios en minería subterránea | C3: ='Hoja 1'!M3 -> El candidato presenta un perfil técnico muy adecuado con sólida experiencia y certificaciones específicas en sistemas contra incendios para minería, lo que se ajusta plenamente al cargo. Su dominio de software es básico pero suficiente para las tareas descritas. La progresión de su carrera muestra crecimiento desde roles técnicos hasta liderazgo. El CV es claro y completo. Sin embargo, la experiencia con software especializado más avanzado podría fortalecer su perfil. | D3: ='Hoja 1'!S3 -> 6.7 | E3: ='Hoja 1'!U3 | F3: ='Hoja 1'!V3 -> Complementariamente, Ángelo ha gestionado adquisiciones y logística de materiales en proyectos de construcción, optimizando entregas y costos, lo cual aporta una visión integral de gestión de recursos en proyectos multidisciplinarios.
A4: ='Hoja 1'!A4 -> Gustavo Adolfo Peña Peña | B4: ='Hoja 1'!R4 -> Supervisor de Proyectos SPCI | C4: ='Hoja 1'!M4 -> El candidato presenta una amplia experiencia técnica y de supervisión en sistemas contra incendios, con sólida formación técnica y certificaciones pertinentes que se alinean bien con los requisitos del cargo. Su experiencia en minería y en la gestión de proyectos similares es una fortaleza importante. Sin embargo, la ausencia del RUT y algunos detalles menores de formalidad en el CV limitan su completitud. En general, es un candidato robusto para cargos relacionados con supervisión y mantenimiento de sistemas SPCI. | D4: ='Hoja 1'!S4 -> 6.4 | E4: ='Hoja 1'!U4 | F4: ='Hoja 1'!V4 -> Adicionalmente, ha trabajado en telecomunicaciones realizando empalmes de fibra óptica y en planificación administrativa y gestión de cartera de clientes, supervisando trabajos de mantenimiento preventivo y correctivo, lo que añade valor en gestión de recursos y comunicación con mandantes.
A5: ='Hoja 1'!A5 -> Rodrigo Alejandro Bruna Pastenes | B5: ='Hoja 1'!R5 -> Técnico de mantenimiento en maquinaria pesada para minería subterránea | C5: ='Hoja 1'!M5 -> Rodrigo presenta un perfil profesional acorde a cargos técnicos en maquinaria pesada para minería subterránea, con una formación sólida y experiencia progresiva en el rubro. Sin embargo, la ausencia de información sobre dominio de software limita la evaluación tecnológica. Su CV es claro pero con poca evidencia sobre proyectos o certificaciones adicionales, afectando la nota final que se ubica en un rango satisfactorio pero con oportunidad de mejora en especialización y herramientas tecnológicas. | D5: ='Hoja 1'!S5 -> 5.7 | E5: ='Hoja 1'!U5 | F5: ='Hoja 1'!V5 -> Anteriormente trabajó como ayudante mecánico y realizó prácticas en talleres automotrices, lo que complementa su experiencia técnica con un conocimiento básico en mantenimiento automotriz y apoyo en talleres, aportando habilidades transferibles en mecánica general.
A6: ='Hoja 1'!A6 -> Carlos A. Hernández | B6: ='Hoja 1'!R6 | C6: ='Hoja 1'!M6 -> El candidato presenta un perfil técnico sólido y muy adecuado para cargos relacionados con ingeniería eléctrica e instrumentación en sectores industriales y mineros, con más de 15 años de experiencia relevante y dominio avanzado de software técnico. Su trayectoria muestra una clara progresión en responsabilidades y liderazgo de proyectos complejos. El CV es claro y detallado, aunque podría mejorar la inclusión de datos de contacto telefónico. En conjunto, es un candidato muy competitivo para posiciones de ingeniería de proyectos en electricidad e instrumentación. | D6: ='Hoja 1'!S6 -> 6.7 | E6: ='Hoja 1'!U6 | F6: ='Hoja 1'!V6 -> Experiencia previa en Venezuela como Coordinador de Ingeniería y proyectos eléctricos en sectores de energía, telecomunicaciones y petroquímica, desarrollando normativas, estudios eléctricos y automatización, así como en supervisión de obras y coordinación multidisciplinaria en proyectos de infraestructura pública y residencial.
A7: ='Hoja 1'!A7 -> Angelo Fabian Stevens Stevens | B7: ='Hoja 1'!R7 | C7: ='Hoja 1'!M7 -> El candidato presenta un perfil sólido y adecuado para cargos relacionados con supervisión técnica y gestión de sistemas de seguridad contra incendios en industrias mineras, apoyado por experiencia práctica y certificaciones especializadas. Su experiencia en proyectos similares y manejo de software relevante es adecuada, aunque su formación académica universitaria aún está en curso y puede representar una oportunidad de mejora. El CV es claro y detallado, reflejando progresión y responsabilidad creciente en su carrera. | D7: ='Hoja 1'!S7 -> 5.8 | E7: ='Hoja 1'!U7 | F7: ='Hoja 1'!V7 -> Ha desarrollado experiencia complementaria en control documental y gestión administrativa dentro de proyectos industriales, incluyendo manejo avanzado de herramientas informáticas y coordinación con diversas áreas para la fiscalización de procesos y control de personal, además de labores logísticas y administrativas en terreno.
A8: ='Hoja 1'!A8 -> Víctor Andrés Escobar Serey | B8: ='Hoja 1'!R8 -> Supervisor de sistemas contra incendio | C8: ='Hoja 1'!M8 -> El candidato muestra una alta adecuación para cargos relacionados con la supervisión de sistemas contra incendios en industrias críticas, con amplia experiencia y formación técnica acorde. Su dominio en programación Notifier y planificación de mantenimiento son fortalezas clave. Sin embargo, la formación en ingeniería está en progreso y podría requerir actualización de licencias para ciertos aspectos del cargo. Su CV es claro y completo en cuanto a experiencia técnica específica. | D8: ='Hoja 1'!S8 -> 6.5 | E8: ='Hoja 1'!U8 | F8: ='Hoja 1'!V8 -> Además de su especialización en sistemas contra incendio, Víctor tiene formación técnica en mecánica automotriz y estudios en ingeniería mecánica, lo que aporta una base sólida en aspectos técnicos y administrativos. También cuenta con habilidades en Autocad y Microsoft Office, que complementan sus funciones de planificación y supervisión.
A9: ='Hoja 1'!A9 -> Oscar Antonio Cabello Fuentes | B9: ='Hoja 1'!R9 -> Supervisor de Seguridad y Mantenimiento en Minería | C9: ='Hoja 1'!M9 -> El candidato presenta un perfil altamente adecuado para cargos de supervisión en seguridad y mantenimiento de sistemas de protección contra incendios en minería, con una sólida formación técnica y extensa experiencia práctica en División Andina de Codelco. Su dominio de protocolos de seguridad y herramientas técnicas es amplio, aunque limitado en herramientas informáticas específicas más allá del manejo básico de PC. La progresión laboral es clara y congruente con el cargo actual. El CV es detallado, aunque puede mejorar en estructuración para facilitar la lectura. | D9: ='Hoja 1'!S9 -> 6.5 | E9: ='Hoja 1'!U9 | F9: ='Hoja 1'!V9 -> Cuenta con amplia experiencia como voluntario en bomberos durante 23 años, lo que complementa su perfil en manejo de emergencias y respuesta frente a incendios. También ha desempeñado cargos como prevencionista de riesgos, desarrollando capacitaciones y controles administrativos en obras civiles y operaciones mineras.
A10: ='Hoja 1'!A10 -> Robinson Patricio Tapia Venegas | B10: ='Hoja 1'!R10 -> Técnico Especialista en mantenimiento y sistemas contra incendio en minería | C10: ='Hoja 1'!M10 -> El candidato presenta un perfil profesional adecuado al cargo de Técnico Especialista en mantenimiento y sistemas de protección contra incendios, con una sólida formación técnica y 11 años de experiencia relevante, incluyendo 6 años en el cargo actual. Domina herramientas y normativas relevantes para el sector y muestra una trayectoria coherente con progresión y especialización. El CV es claro y completo, aunque podría incluir más detalles cuantitativos sobre logros específicos. | D10: ='Hoja 1'!S10 -> 6.6 | E10: ='Hoja 1'!U10 | F10: ='Hoja 1'!V10 -> Experiencia previa en mantenimiento electromeánico y mecánico en la empresa Buses JM trabajando en mantenimiento preventivo y correctivo de equipos mecánicos, neumáticos e hidráulicos, en ambientes urbanos y mineros, sumando conocimientos en diagnósticos técnicos y gestión de registros de mantenimiento.
A11: ='Hoja 1'!A11 -> Eduardo Andrés Maldonado Cerón | B11: ='Hoja 1'!R11 -> Técnico de Mantención Industrial en Minería | C11: ='Hoja 1'!M11 -> El candidato posee un perfil técnico fuerte y experiencia relevante en mantenimiento de maquinaria pesada y sistemas mecánicos relacionados con minería y producción industrial. Su historial muestra estabilidad y progresión en roles de mayor complejidad técnica y liderazgo. La carencia de mención de software o herramientas digitales limita un poco su adecuación tecnológica. En general, presenta una buena base para cargos técnicos especializados en mantenimiento industrial y minero. | D11: ='Hoja 1'!S11 -> 6.4 | E11: ='Hoja 1'!U11 | F11: ='Hoja 1'!V11 -> Ha desempeñado también funciones en logística interna como bodeguero, operador de grúa horquilla y recepción, además de roles en producción y operación de maquinaria diversa como fresadoras y empaquetadoras en sectores industriales variados.
A12: ='Hoja 1'!A12 -> Mauricio Andrés González Valerio | B12: ='Hoja 1'!R12 -> Jefe de área en sistema contra incendio | C12: ='Hoja 1'!M12 -> El candidato posee un perfil técnico sólido y altamente especializado en sistemas contra incendio, con experiencia práctica significativa y conocimiento de normativas relevantes. Su formación y experiencia en ingeniería son adecuadas para el cargo. Sin embargo, el manejo de software está limitado a nivel medio y podría mejorar para optimizar su desempeño. La progresión de carrera es clara y pertinente, aunque el CV presenta algunos saltos en roles que no son del todo coherentes en términos de evolución laboral. | D12: ='Hoja 1'!S12 -> 6.3 | E12: ='Hoja 1'!U12 | F12: ='Hoja 1'!V12 -> Posee experiencia adicional en instalación de sistemas de telecomunicaciones, redes, climatización industrial y control industrial, además de roles en logística y control de insumos en el ámbito educativo, lo que aporta un perfil versátil y capacidad para funciones administrativas y de soporte técnico complementarias.
A13: ='Hoja 1'!A13 -> JUSTIN FRANCISCO ROJAS OLGUIN | B13: ='Hoja 1'!R13 -> Supervisor de Sistemas de Automatización y Control Industrial | C13: ='Hoja 1'!M13 -> El candidato presenta una sólida formación técnica y una amplia experiencia de más de 12 años en áreas relevantes para cargos de supervisión y operación en automatización y sistemas contra incendio, con roles recientes de liderazgo. Su dominio de software es básico, pero adecuado para su especialidad. La progresión en su carrera es clara, destacando responsabilidades crecientes. Su CV es claro y detallado, aunque podría mejorar la presentación para facilitar la extracción de datos. | D13: ='Hoja 1'!S13 -> 6.3 | E13: ='Hoja 1'!U13 | F13: ='Hoja 1'!V13 -> Ha desarrollado labores complementarias como instalador y programador de telecomunicaciones, montaje de torres para distribución de Internet en zonas rurales, mantenimiento electromecánico y trabajó en instalación y reparación de equipos de climatización industrial y residencial, aportando versatilidad y conocimiento en diversas áreas técnicas relacionadas.
... A572: ='Hoja 1'!A572 | B572: ='Hoja 1'!R572 | C572: ='Hoja 1'!M572 | D572: ='Hoja 1'!S572 | E572: ='Hoja 1'!U572 | F572: ='Hoja 1'!V572

Sheet Hoja 1
A1: nombre_completo | B1: rut | C1: fecha_nacimiento | D1: correo | E1: telefono | F1: profesion | G1: experiencia | H1: software_que_domina | I1: ultima_exp_laboral_empresa | J1: cargo | K1: periodo | M1: evaluacion_general | N1: experiencia_total | O1: experiencia_en_empresa_actual | P1: exp_cargo_actual | Q1: exp_proy_similares | R1: cargo_a_desempeñar | S1: nota | T1: ranking | U1: conocimientos_especificos | V1: otras_experiencias | W1: estado | X1: id_candidato | Y1: data | Z1: experiencia_general | AA1: experiencia_especifica | AB1: antecedentes_academicos
A2: Isaí Jara Maldonado | B2: 15.585.862-1 | C2: 30455 | D2: ijara.m83@gmail.com | E2: #ERROR! | F2: Ingeniero Civil Industrial | G2: Ingeniero de Proyectos SPCI, Eurocomercial LTDA, Mar. 2023 – Al Presente | Supervisor de Mantenimiento SPCI, SFR, S.P.A., Jul. 2020 – Mar. 2023 | Representante Comercial, Vetech, LTDA., Mar. 2019 – Jun. 2020 | Supervisor de Servicios, Polex Chile, Mar. 2014 – Feb. 2019 | H2: Power BI, Microsoft Office | I2: Eurocomercial LTDA | J2: Ingeniero de Proyectos SPCI | K2: Mar. 2023 – Al Presente | M2: El candidato presenta un perfil profesional muy adecuado para el cargo, con sólida formación académica y experiencia directa en gestión de proyectos SPCI. Su dominio de herramientas como Power BI y Microsoft Office complementan sus habilidades técnicas. La progresión en su carrera muestra un claro avance hacia roles más complejos y de liderazgo. El CV es claro y completo, lo que facilita la evaluación precisa de su idoneidad. | N2: 10.8 | O2: 0.5 | P2: 0.5 | Q2: 3.5 | R2: Ingeniero de Proyectos SPCI | S2: 6.5 | V2: Ha desarrollado funciones complementarias como representante comercial y supervisor de servicios, donde gestionó relaciones con clientes, elaboró informes de rendimiento y organizó equipos de trabajo, habilidades que fortalecen su capacidad de comunicación, organización y atención a la calidad del servicio. | Z2: Isaí Jara Maldonado es un Ingeniero Civil Industrial con más de 10 años de experiencia laboral en diversos roles relacionados con la gestión de proyectos, supervisión de mantenimiento y servicios, así como representación comercial. Su trayectoria profesional se ha desarrollado principalmente en chilenas, mostrando habilidades en la planificación estratégica, control de proyectos, manejo de presupuestos y liderazgo de equipos en sectores industriales y comerciales. Destaca por su orientación a la mejora continua y la gestión eficiente de recursos. | AA2: Cuenta con experiencia específica en gestión y supervisión de proyectos SPCI, donde ha sido responsable de la identificación y mitigación de riesgos, elaboración de cronogramas, control presupuestario y coordinación entre actores del proyecto. Además, supervisó actividades de mantenimiento preventivo y correctivo con enfoque en cumplimiento de normativas de seguridad, demostrando competencias sólidas en planificación técnica y operativa para proyectos similares al cargo requerido. | AB2: Posee un título profesional de Ingeniero Civil Industrial de la Universidad San Sebastian (2017-2021), junto con cursos de ingeniería de ejecución en sonido y técnica en electrónica. Actualmente cursa dos másteres en Administración y Dirección de Empresas (MBA) y en Project Management en la Escuela de Negocios Europea de Barcelona, aportando formación avanzada y actualizada en gestión empresarial y proyectos.
A3: Ángelo Ignacio Pérez Arancibia | C3: 33485 | D3: Ignacio.angelo.ph@gmail.com | E3: -37677823 | F3: Técnico en Construcción | G3: CMPC Laja, Técnico líder montaje de red húmeda en sistemas contra incendios EW, 2009 - 2012 | SP GLOBAL, Especialista SAPCI montaje de sistema supresor en equipos móviles, 2012 - 2015 | Constructora Loma Verde, Encargado de adquisiciones, 2015 - 2019 | SERCOING, DCH, Técnico líder en sistemas contra incendios, 2019 - Actualidad | H3: AutoCAD, Excel | I3: SERCOING, DCH | J3: Técnico líder en sistemas contra incendios | K3: 2019 - Actualidad | M3: El candidato presenta un perfil técnico muy adecuado con sólida experiencia y certificaciones específicas en sistemas contra incendios para minería, lo que se ajusta plenamente al cargo. Su dominio de software es básico pero suficiente para las tareas descritas. La progresión de su carrera muestra crecimiento desde roles técnicos hasta liderazgo. El CV es claro y completo. Sin embargo, la experiencia con software especializado más avanzado podría fortalecer su perfil. | N3: 13.5 | O3: 4.5 | P3: 4.5 | Q3: 8 | R3: Técnico líder en sistemas de protección contra incendios en minería subterránea | S3: 6.7 | V3: Complementariamente, Ángelo ha gestionado adquisiciones y logística de materiales en proyectos de construcción, optimizando entregas y costos, lo cual aporta una visión integral de gestión de recursos en proyectos multidisciplinarios. | Z3: Ángelo cuenta con más de 13 años de experiencia en el sector minero y de la construcción, especializado en sistemas contra incendios para equipos móviles y proyectos de construcción. Ha trabajado en montaje, supervisión y mantenimiento de sistemas de supresión, además de gestión de adquisiciones y planificación. Posee habilidades técnicas en electricidad básica, cubicación y gestión digital con AutoCAD y Excel, lo que le permite optimizar recursos y coordinar equipos en ambientes de alta exigencia minera. | AA3: Su experiencia específica incluye la instalación, inspección y mantenimiento de sistemas de supresión de incendios en equipos móviles de minería subterránea para Codelco, liderando equipos y asegurando el cumplimiento de normativas nacionales e internacionales. Ha coordinado proyectos de montaje de sistemas húmedos y supresores en equipos críticos como camiones y palas, capacitando personal en el uso de estos sistemas y gestionando estándares de seguridad minera. | AB3: Posee formación técnica en Construcción del Instituto Profesional Duoc UC, además de certificaciones NFPA 10, 13, 25 y 72 que avalan su especialización en sistemas contra incendios. Su educación formal incluye educación básica y media completadas en Chile.
A4: Gustavo Adolfo Peña Peña | C4: 32388 | D4: g.adolfopena@gmail.com | E4: #ERROR! | F4: Técnico Superior Electricidad y Electrónica | G4: Técnico SPCI en Ignacio Peña LTDA, Santiago (Ene 2007 - Ene 2008) | Técnico Telecomunicaciones en CF Ingenieria, Santiago (Feb 2008 - Nov 2012) | Supervisor de Obras SPCI en Protego S.A, Santiago (Nov 2012 - Mar 2017) | Supervisor de Obras SPCI en Stat-Fire, Santiago (Mar 2017 - Mar 2023) | Jefe de Mantenimiento / Adm Contratos SPCI en Stat-Fire, Santiago (Jul 2018 – Mar 2023) | Jefe Mantención y Servicios SPCI en FIRECON, Santiago (Abr 2023 – Dic 2023) | Especialista SAPCI en Ferrostaal Chile S.A.C (Ene 2024 - Jun 2024) | H4: SAP, NFPA25, Paneles Notifier, Simplex, Bosh, ASD-535, ADW, Carta Gantt | I4: Ferrostaal Chile S.A.C | J4: Especialista SAPCI | K4: Enero 2024 - Junio 2024 | M4: El candidato presenta una amplia experiencia técnica y de supervisión en sistemas contra incendios, con sólida formación técnica y certificaciones pertinentes que se alinean bien con los requisitos del cargo. Su experiencia en minería y en la gestión de proyectos similares es una fortaleza importante. Sin embargo, la ausencia del RUT y algunos detalles menores de formalidad en el CV limitan su completitud. En general, es un candidato robusto para cargos relacionados con supervisión y mantenimiento de sistemas SPCI. | N4: 17.5 | O4: 0.5 | P4: 0.5 | Q4: 10 | R4: Supervisor de Proyectos SPCI | S4: 6.4 | V4: Adicionalmente, ha trabajado en telecomunicaciones realizando empalmes de fibra óptica y en planificación administrativa y gestión de cartera de clientes, supervisando trabajos de mantenimiento preventivo y correctivo, lo que añade valor en gestión de recursos y comunicación con mandantes. | Z4: Gustavo Peña posee más de 17 años de experiencia en sistemas de protección contra incendios (SPCI) y telecomunicaciones con fuerte enfoque en la instalación, supervisión y mantenimiento de sistemas de detección y extinción contra incendios. Ha trabajado principalmente en el sector minero y empresas industriales, liderando proyectos de implementación de sistemas avanzados en diferentes regiones de Chile y manejando equipos multifuncionales de trabajo con responsabilidad en planificación y presupuestos. | AA4: Ha desarrollado una sólida experiencia en la supervisión y mantenimiento de sistemas SPCI en minería, con conocimiento profundo en normativas NFPA, y manejo de paneles como Notifier, Simplex y Bosh. Se ha encargado de la instalación y mantenimiento de sistemas de detección y extinción basados en tecnologías como aerosol condensado, F-200 y Novec 1230, específicamente en salas eléctricas, correas transportadoras y bodegas industriales, además de liderar equipos y planificación detallada en obras de alto estándar técnico. | AB4: Es Técnico Superior en Electricidad y Electrónica titulado en Duoc UC. Posee certificaciones en NFPA25 para inspección, pruebas y mantenimiento de sistemas contra incendio a base de agua, cursos de ingeniería, puesta en marcha y mantenimiento dictados por Securiton AG, y formación en diseño y configuración de sistemas Notifier, además de especializaciones en sistemas preventivos para trabajos de alto riesgo.
A5: Rodrigo Alejandro Bruna Pastenes | B5: 19.538.079-1 | C5: 35422 | D5: rodrigo.bruna.pastenes@gmail.com | E5: -74944353 | F5: Ingeniero en Maquinaria Pesada y Vehículos Automotrices | G5: Técnico especialista sapci, subterránea, en SERCOING LTDA, Calama (2021 – 2024) | Técnico especialista sapci en Empresa SERCOING LTDA, Calama (2020) | Ayudante mecánico en taller ALDATA, Calama (2019) | Realización de práctica en taller REY DE REYES, Calama (2017) | I5: SERCOING LTDA | J5: Técnico especialista sapci, subterránea | K5: 2021 – 2024 | M5: Rodrigo presenta un perfil profesional acorde a cargos técnicos en maquinaria pesada para minería subterránea, con una formación sólida y experiencia progresiva en el rubro. Sin embargo, la ausencia de información sobre dominio de software limita la evaluación tecnológica. Su CV es claro pero con poca evidencia sobre proyectos o certificaciones adicionales, afectando la nota final que se ubica en un rango satisfactorio pero con oportunidad de mejora en especialización y herramientas tecnológicas. | N5: 7 | O5: 4 | P5: 4 | Q5: 4 | R5: Técnico de mantenimiento en maquinaria pesada para minería subterránea | S5: 5.7 | V5: Anteriormente trabajó como ayudante mecánico y realizó prácticas en talleres automotrices, lo que complementa su experiencia técnica con un conocimiento básico en mantenimiento automotriz y apoyo en talleres, aportando habilidades transferibles en mecánica general. | Z5: Rodrigo cuenta con aproximadamente 7 años de experiencia laboral acumulada, iniciando en 2017 con prácticas y trabajos en talleres mecánicos y ha progresado hasta roles técnicos especialistas en el área subterránea para la empresa SERCOING LTDA. Su trayectoria se centra en el rubro de maquinaria pesada y vehículos automotrices, con un fuerte enfoque en trabajos técnicos en minería subterránea, demostrando capacidades para adaptarse y aprender en entornos especializados. | AA5: Ha desempeñado funciones como técnico especialista sapci en minería subterránea, trabajando para SERCOING LTDA entre 2020 y 2024. Su rol implicó manejo técnico en maquinaria pesada, alineado con mantenimiento y operación en el contexto subterráneo, lo que es pertinente para cargos relacionados con la operación y mantención de equipamiento minero. | AB5: Cuenta con un título profesional de Ingeniero en Maquinaria Pesada y Vehículos Automotrices otorgado en 2021 por el Instituto Profesional INACAP, además de un título técnico en la misma área obtenido en 2017, respaldando su formación técnica y profesional asociada a maquinaria pesada y vehículos.
A6: Carlos A. Hernández | B6: 26.246.917-4 | C6: 30752 | D6: cahernandez.cl@gmail.com | F6: Ingeniero Civil en Electricidad | G6: INGEC SPA | Ingeniero de proyectos | 2019-Actualidad | INGEC LTDA | Ingeniero de proyectos | 2018-2019 | INVERSIONES CVMJ 2014 C.A. | Coordinador de Ingeniería / Ingeniero de proyectos eléctricos | 2015-2018 | CONSTRUCCIONES MG, C.A. | Ingeniero Residente / Ingeniero Eléctrico | 2010-2014 | H6: Microsoft Office, Automation Studio, Etap, SolidWorks Electrical 3D, DigSilent PowerFactory, RsLogix, Dialux, Microsoft Project, Autocad, Primavera P6, PVSyst, Valve Specs, SmartPlant PI&D, ElecWorks, SmartPlant Electrical, SmartPlant Instrumentation | I6: INGEC SPA | J6: Ingeniero de proyectos | K6: 2019-Actualidad | M6: El candidato presenta un perfil técnico sólido y muy adecuado para cargos relacionados con ingeniería eléctrica e instrumentación en sectores industriales y mineros, con más de 15 años de experiencia relevante y dominio avanzado de software técnico. Su trayectoria muestra una clara progresión en responsabilidades y liderazgo de proyectos complejos. El CV es claro y detallado, aunque podría mejorar la inclusión de datos de contacto telefónico. En conjunto, es un candidato muy competitivo para posiciones de ingeniería de proyectos en electricidad e instrumentación. | N6: 15 | O6: 5 | P6: 5 | Q6: 10 | S6: 6.7 | V6: Experiencia previa en Venezuela como Coordinador de Ingeniería y proyectos eléctricos en sectores de energía, telecomunicaciones y petroquímica, desarrollando normativas, estudios eléctricos y automatización, así como en supervisión de obras y coordinación multidisciplinaria en proyectos de infraestructura pública y residencial. | Z6: Profesional con más de 15 años de experiencia en ingeniería eléctrica, instrumentación y control en minería, industria petrolera, petroquímica y minería de litio y cobre. Ha desarrollado proyectos desde ingeniería de perfil hasta de detalle, con amplia experiencia en estudios eléctricos, diseño de sistemas de control y liderazgo de equipos interdisciplinarios, además de supervisión en construcción y puesta en marcha. | AA6: Amplia experiencia en desarrollo de proyectos de ingeniería eléctrica e instrumentación para la gran minería y sectores industriales, incluyendo electromovilidad, estaciones de servicio, sistemas eléctricos de media y baja tensión, y proyectos específicos para CODELCO y otras empresas mineras relevantes. Ha liderado y participado en proyectos de ingeniería básica, perfil, detalle y prefactibilidad, con enfoque en electricidad, instrumentación y control, además de manejo y diseño con sistemas SCADA y arquitecturas de control industrial. | AB6: Titulado en Ingeniería Civil en Electricidad por la Universidad de Chile (revalidación), con títulos de postgrado en Gerencia de Mantenimiento y Especialización en Automatización e Informática Industrial por la Universidad de Oriente, Venezuela. Además, posee formación técnica previa en Tecnología en Electrónica y variados cursos en seguridad, mantenimiento, electrónica de potencia y conducción defensiva. Cuenta con licencia de conducir clase B y dominio avanzado de inglés.
A7: Angelo Fabian Stevens Stevens | B7: 18051532-1 | D7: angelo.stevens@outlook.com | E7: (+56) 9 3435 8980 | F7: Especialista técnico sseir | G7: Especialista técnico en incendios SAPCI – Sigma Codelco Chuquicamata (Abr 2022 – Nov 2022) | Supervisor de brigada Minera Escondida BHP - Jonhson Control (Ene 2021 – Abr 2022) | Especialista sseir Militar en Fuerza aérea de chile (Oct 2015 – Dic 2020) | Control Documents – International Steel Detailing – Arrigoni Ingeniería (Ene 2010 – Oct 2015) | Project assistant Arrigoni Metalúrgica (Ene 2009 – Ene 2010) | H7: SAP, AutoCAD Viewer, Tekla Structures, Microsoft Office (Excel avanzado con macros), MS Access, SQL (básico) | I7: Sigma Codelco Chuquicamata | J7: Especialista técnico en incendios SAPCI | K7: Abr 2022 – Nov 2022 | M7: El candidato presenta un perfil sólido y adecuado para cargos relacionados con supervisión técnica y gestión de sistemas de seguridad contra incendios en industrias mineras, apoyado por experiencia práctica y certificaciones especializadas. Su experiencia en proyectos similares y manejo de software relevante es adecuada, aunque su formación académica universitaria aún está en curso y puede representar una oportunidad de mejora. El CV es claro y detallado, reflejando progresión y responsabilidad creciente en su carrera. | N7: 14.5 | O7: 0.6 | P7: 0.6 | Q7: 2.5 | S7: 5.8 | V7: Ha desarrollado experiencia complementaria en control documental y gestión administrativa dentro de proyectos industriales, incluyendo manejo avanzado de herramientas informáticas y coordinación con diversas áreas para la fiscalización de procesos y control de personal, además de labores logísticas y administrativas en terreno. | Z7: Angelo Stevens posee una trayectoria laboral de más de 13 años en roles técnicos y de supervisión, principalmente en áreas relacionadas con incendios, seguridad industrial y control documental en industrias mineras y militares. Ha desempeñado cargos de liderazgo en manejo de equipos y supervisión, integrando conocimiento técnico en mantención y control de sistemas críticos, con fuerte enfoque en cumplimiento de normas de seguridad y administración de procesos. | AA7: Cuenta con experiencia específica en supervisión e inspección de sistemas contra incendios, mantención de equipos SAPCI Notifier NFS-320 y gestión de emergencias industriales en importantes empresas mineras como Codelco y Minera Escondida, además de certificación internacional en manejo de mercancías peligrosas (HAZMAT). Ha liderado brigadas y gestionado protocolos de seguridad y logística crítica en faenas mineras. | AB7: Actualmente cursa Ingeniería en Finanzas en la Escuela de Comercio de Santiago y es técnico graduado como Especialista técnico sseir en la Escuela Técnica Aeronáutica Civil. Posee una certificación internacional en gestión de mercancías peligrosas HAZMAT, y conocimientos intermedios en MS Access, básico en SQL, así como manejo avanzado de Microsoft Office con macros.
A8: Víctor Andrés Escobar Serey | B8: 17.164.461-5 | C8: 32668 | D8: victorescobarserey@gmail.com | E8: #ERROR! | F8: Técnico a nivel superior en Mecánica Automotriz (en curso Ingeniería Mecánica) | G8: SERCOING LTDA., Supervisor de confiabilidad del contrato de sistemas contra incendio, Noviembre 2019 – Actualidad | SERCOING LTDA., Supervisor de terreno del contrato de sistemas contra incendio, Enero 2018 – Octubre 2019 | MAXIMILIANO GONZALEZ Y CIA LTDA., Supervisor de terreno del contrato de sistemas contra incendio, Enero 2016 – Diciembre 2017 | MAXIMILIANO GONZALEZ Y CIA LTDA., Técnico especialista del contrato de sistemas contra incendio, Abril 2014 – Diciembre 2015 | H8: Microsoft Office, Autocad, programación centrales Notifier Modelos NFS 320, 640, 3030 | I8: SERCOING LTDA. | J8: Supervisor de confiabilidad del contrato de sistemas contra incendio | K8: Noviembre 2019 – Actualidad | M8: El candidato muestra una alta adecuación para cargos relacionados con la supervisión de sistemas contra incendios en industrias críticas, con amplia experiencia y formación técnica acorde. Su dominio en programación Notifier y planificación de mantenimiento son fortalezas clave. Sin embargo, la formación en ingeniería está en progreso y podría requerir actualización de licencias para ciertos aspectos del cargo. Su CV es claro y completo en cuanto a experiencia técnica específica. | N8: 9.5 | O8: 3.6 | P8: 3.6 | Q8: 9.5 | R8: Supervisor de sistemas contra incendio | S8: 6.5 | V8: Además de su especialización en sistemas contra incendio, Víctor tiene formación técnica en mecánica automotriz y estudios en ingeniería mecánica, lo que aporta una base sólida en aspectos técnicos y administrativos. También cuenta con habilidades en Autocad y Microsoft Office, que complementan sus funciones de planificación y supervisión. | Z8: Víctor tiene una trayectoria de más de 9 años en supervisión y mantenimiento de sistemas contra incendios en la industria minera, principalmente en Codelco División Andina. Ha desempeñado cargos desde técnico especialista hasta supervisor de confiabilidad, liderando equipos y gestionando proyectos de inspección, mantenimiento y mejoras en sistemas detectores y de supresión de incendios. Posee experiencia en programación de centrales y aplicación de estándares de seguridad. | AA8: Posee amplia experiencia supervisando sistemas contra incendio, incluyendo programación de centrales Notifier (Modelos NFS 320, 640 y 3030) y mantenimiento de sistemas automáticos de detección y extinción. Ha sido responsable de la planificación, control y supervisión de estos sistemas en un entorno industrial de alta exigencia, garantizando el cumplimiento de estándares de seguridad y la ejecución de proyectos de mejora continua en Codelco División Andina. | AB8: Cursando 4º semestre de Ingeniería Mecánica en Universidad Aconcagua. Técnico nivel superior en Mecánica Automotriz por Instituto Profesional Inacap. Técnico nivel medio en Administración de Empresas. Capacitado con licencia de programador Notifier vigente hasta septiembre 2022. Cursos de NFPA 72, 12, 25, 10 y NFPA 75 con vigencia y certificaciones reconocidas.
A9: Oscar Antonio Cabello Fuentes | B9: 12.008.095-4 | C9: 29463 | D9: oacabello@gmail.com | E9: 9 84667365 | F9: Técnico Mecánico, Prevencionista de Riesgos | G9: Sercoing: Supervisor en División Andina Codelco Chile, Marzo 2018 – Actualidad | Antolín Cisternas: Prevencionista de Riesgos, Junio 2017 | Metrika: Supervisor Mecánico y ODS en División Andina Codelco Chile, Enero 2014 – Junio 2017 | WILUG LTDA: Mecánico mantenedor de sistemas supresores de incendio en División Andina Codelco Chile, Abril 2006 – 2007 | PROCIN SA: Mecánico mantenedor de sistemas supresores de incendio en División Andina Codelco Chile, 2004 – Marzo 2006 | EMASIC: Maestro segunda en minería, División Andina Codelco Chile, 2003 – 2004 | REDPATH: Ayudante mecánico en maquinaria perforadora, División Andina Codelco Chile, 2001 – 2002 | H9: PC a nivel usuario, Sistemas de detección de incendios MXL Siemens, Kidde, Notifier 320 | I9: Sercoing | J9: Supervisor | K9: Marzo 2018 – Actualidad | M9: El candidato presenta un perfil altamente adecuado para cargos de supervisión en seguridad y mantenimiento de sistemas de protección contra incendios en minería, con una sólida formación técnica y extensa experiencia práctica en División Andina de Codelco. Su dominio de protocolos de seguridad y herramientas técnicas es amplio, aunque limitado en herramientas informáticas específicas más allá del manejo básico de PC. La progresión laboral es clara y congruente con el cargo actual. El CV es detallado, aunque puede mejorar en estructuración para facilitar la lectura. | N9: 22 | O9: 5.5 | P9: 5.5 | Q9: 10 | R9: Supervisor de Seguridad y Mantenimiento en Minería | S9: 6.5 | V9: Cuenta con amplia experiencia como voluntario en bomberos durante 23 años, lo que complementa su perfil en manejo de emergencias y respuesta frente a incendios. También ha desempeñado cargos como prevencionista de riesgos, desarrollando capacitaciones y controles administrativos en obras civiles y operaciones mineras. | Z9: Oscar Cabello es un Técnico Mecánico y Prevencionista de Riesgos con más de 20 años de experiencia laboral especialmente en la minería, principalmente en la División Andina de Codelco Chile. Ha desarrollado roles técnicos y de supervisión vinculados a mantenimiento y coordinación de sistemas contra incendios. Posee fortalezas en gestión de seguridad minera, prevención de riesgos y manejo de equipos e inspecciones en ambientes mineros complejos. | AA9: Ha trabajado más de 7 años en roles de supervisión y coordinación de inspecciones y mantenciones de sistemas de protección contra incendios en minería a rajo abierto y subterránea, destacando experiencia técnica en montaje y mantenimiento de redes de incendio húmeda y seca, sistemas de detección de incendios y normativas de seguridad aplicables (NFPA). Cuenta con certificaciones y cursos especializados en seguridad minera y prevención de riesgos. | AB9: Es Técnico Mecánico titulado de INACAP y Técnico en Prevención de Riesgos del ICCE. Cuenta con registro MINSAL como Prevencionista y certificado como Monitor de Seguridad Minera Sernageomin. Ha realizado múltiples cursos y seminarios relacionados con seguridad, manejo de emergencias, trabajo en altura, normativas NFPA, y protocolos de riesgos psicosociales y físicos, además de capacitaciones en conducción defensiva y uso de extintores.
A10: Robinson Patricio Tapia Venegas | B10: 18.972.651-1 | C10: 34582 | D10: robinntapia@gmail.com | E10: 56952013623 | F10: Electromecánico | G10: Sercoing Ltda. Contrato Codelco Chile División Andina - Técnico Especialista - Enero 2018 a la fecha | Buses JM - Técnico Electromecánico - Enero 2015 a diciembre 2017 | Buses JM - Técnico Mecánico - Enero 2013 al noviembre 2014 | Buses JM - Practica laboral - Enero 2012 marzo 2012 | H10: Windows, Excel, Word, Power Point, AutoCAD | I10: Sercoing Ltda. Contrato Codelco Chile División Andina | J10: Técnico Especialista | K10: Enero 2018 a la fecha | M10: El candidato presenta un perfil profesional adecuado al cargo de Técnico Especialista en mantenimiento y sistemas de protección contra incendios, con una sólida formación técnica y 11 años de experiencia relevante, incluyendo 6 años en el cargo actual. Domina herramientas y normativas relevantes para el sector y muestra una trayectoria coherente con progresión y especialización. El CV es claro y completo, aunque podría incluir más detalles cuantitativos sobre logros específicos. | N10: 11 | O10: 6.5 | P10: 6.5 | Q10: 6.5 | R10: Técnico Especialista en mantenimiento y sistemas contra incendio en minería | S10: 6.6 | V10: Experiencia previa en mantenimiento electromeánico y mecánico en la empresa Buses JM trabajando en mantenimiento preventivo y correctivo de equipos mecánicos, neumáticos e hidráulicos, en ambientes urbanos y mineros, sumando conocimientos en diagnósticos técnicos y gestión de registros de mantenimiento. | Z10: Cuenta con 11 años de experiencia laboral en el área de electromecánica, desempeñándose principalmente en mantenimiento, supervisión y montaje de sistemas eléctricos, neumáticos e hidráulicos, con fuerte énfasis en sectores de minería y transporte. Ha desarrollado funciones técnicas y especializadas en empresas de ingeniería y transporte, demostrando responsabilidad, puntualidad y proactividad. | AA10: En su cargo actual como Técnico Especialista en Sercoing Ltda, realiza mantenimiento e inspección de sistemas contra incendio (AFEX, check fire, ANSUL), montaje eléctrico de paneles y sistemas de detección en minería subterránea y rajo. Además, supervisa actividades, coordina con clientes, asegura cumplimiento de normativas de seguridad y prevención de riesgos, y ejecuta mantenciones en sistemas críticos de protección contra incendios. | AB10: Posee título de Técnico de Nivel Medio en Mecánica Automotriz y Técnico de Nivel Superior en Electricidad. Complementa su formación con diversas capacitaciones en normativas NFPA (10, 25, 72, 75), cursos de aislamiento y bloqueo, trabajo en altura, conducción en minería, y uso de herramientas ofimáticas y AutoCAD, además de licencia de conducir Clase B-D y exámenes ocupacionales vigentes.
A11: Eduardo Andrés Maldonado Cerón | B11: 16.528.513-1 | C11: 31720 | D11: edu_maldo24@hotmail.com | E11: 942540747, 961833383 | F11: Técnico Superior en Mantenimiento Industrial | G11: 2005 Empresa Bticino, Rengo - Mecánico industrial, Operador de fresadora convencional | 2005 Empresa Geofrut, Rengo - Ayudante de Mecánico | 2006-2008 Empresa Bticino, Rengo - Bodeguero Operador Grúa Horquilla, Recepcionista y Despachador | 2009 Empresa Agrofood, Malloa - Ayudante Operador de Coker y Cooler | 2010 Empresa Invertec, Rengo - Operador calificado y encargado de cuadrilla | 2010 Empresa Aguas CCU Nestlé, Cachantun, Coinco - Operador Mantenedor, Paletizador de producto | 2010 Viña Anakena, Requinoa - Electromecánico | 2010-2012 Empresa Aguas CCU Nestlé, Cachantun, Coinco - Operador Mantenedor | 2012-2017 Empresa Ferrostaal Contratista El Teniente Codelco - Mecánico A / Mantenedor M1, inspector de herramientas mecánicas | 2017-2018 Empresa Metrika Contratista El Teniente Codelco - Mantención sistema contra incendios equipos pesados | 2018 Agosto-Octubre Empresa Westfire Contratista El Teniente Codelco - Mantención sistema contra incendios equipos pesados | 2018-2020 Empresa Sercoing Contratista El Teniente Codelco - Mantención sistema contra incendios equipos pesados | Enero 2021 – Enero 2022 Empresa Movitec Mina Spence Sierra Gorda - Mecánico maquinaria pesada | Febrero 2022 – Mayo 2022 Empresa Consorcio 2M - Mantención camiones y maquinaria pesada | Junio 2022 – Enero 2023 Empresa Consorcio Belaz Movitec - Mantención y reparación Caex Belaz y maquinaria pesada | Marzo 2023 – Mayo 2023 Empresa Relix WATER - Reparación y cambio de componentes maquinaria pesada | I11: Relix WATER | J11: Técnico mecánico / mantenimiento maquinaria pesada | K11: Marzo 2023 – Mayo 2023 | M11: El candidato posee un perfil técnico fuerte y experiencia relevante en mantenimiento de maquinaria pesada y sistemas mecánicos relacionados con minería y producción industrial. Su historial muestra estabilidad y progresión en roles de mayor complejidad técnica y liderazgo. La carencia de mención de software o herramientas digitales limita un poco su adecuación tecnológica. En general, presenta una buena base para cargos técnicos especializados en mantenimiento industrial y minero. | N11: 18 | O11: 0.3 | P11: 0.3 | Q11: 7 | R11: Técnico de Mantención Industrial en Minería | S11: 6.4 | V11: Ha desempeñado también funciones en logística interna como bodeguero, operador de grúa horquilla y recepción, además de roles en producción y operación de maquinaria diversa como fresadoras y empaquetadoras en sectores industriales variados. | Z11: Eduardo Andrés Maldonado Cerón es un técnico superior en mantenimiento industrial con más de 18 años de experiencia laboral progresiva en sectores industriales y mineros. Ha desarrollado habilidades en mantenimiento mecánico, electromecánico y manejo de maquinaria pesada, trabajando en entornos de producción, mantenimiento preventivo y correctivo, y supervisión de equipos en empresas de gran tamaño, especialmente en minería y producción industrial. Su experiencia incluye roles técnicos y de coordinación con enfoque en la optimización de producción y seguridad. | AA11: Cuenta con amplia experiencia en mantenimiento y reparación de sistemas mecánicos y móviles en minería, incluyendo mantención de equipos LHD, Jumbos, manipuladores, camiones de gran tonelaje y sistemas contra incendios, demostrando conocimiento técnico en frenos, suspensión, sistemas eléctricos y neumáticos, además de liderar tareas de inspección y supervisión en plantas mineras como Codelco y proyectos en Mina Spence, Sierra Gorda y Belaz. | AB11: Formación técnica en Mecánica Industrial a nivel medio en Liceo Politécnico Tomas Marín de Poveda y Técnico Superior en Mantenimiento Industrial obtenido en Universidad Tecnológica Inacap en 2010. Complementa su formación con cursos empresariales y de seguridad como brigada de incendios, primeros auxilios y uso de extintores.
A12: Mauricio Andrés González Valerio | B12: 19.604.579-1 | D12: mauricio.97.mgmg@gmail.com | E12: 56982554101 | F12: Ingeniero en Maquinaria, Vehículos Automotrices y Sistemas Electrónicos | G12: Jefe de área en sistema contra incendio - Sercoing Ltda | Abril 2021 - a la fecha | Especialista en sistema contra incendio - Sercoing Ltda | Febrero 2020 - abril 2021 | Capataz - Jenergia SPA | Febrero 2017 - actualidad | Pañolero / Bodeguero - INACAP (Rancagua) | Febrero 2016 - enero 2017 | H12: Excel nivel medio, Autocad nivel medio, Programación de centrales inteligentes NOTIFIER | I12: Sercoing Ltda | J12: Jefe de área en sistema contra incendio | K12: Abril 2021 - a la fecha | M12: El candidato posee un perfil técnico sólido y altamente especializado en sistemas contra incendio, con experiencia práctica significativa y conocimiento de normativas relevantes. Su formación y experiencia en ingeniería son adecuadas para el cargo. Sin embargo, el manejo de software está limitado a nivel medio y podría mejorar para optimizar su desempeño. La progresión de carrera es clara y pertinente, aunque el CV presenta algunos saltos en roles que no son del todo coherentes en términos de evolución laboral. | N12: 7.5 | O12: 3.2 | P12: 3.2 | Q12: 4 | R12: Jefe de área en sistema contra incendio | S12: 6.3 | V12: Posee experiencia adicional en instalación de sistemas de telecomunicaciones, redes, climatización industrial y control industrial, además de roles en logística y control de insumos en el ámbito educativo, lo que aporta un perfil versátil y capacidad para funciones administrativas y de soporte técnico complementarias. | Z12: Mauricio es Ingeniero en Maquinaria, Vehículos Automotrices y Sistemas Electrónicos con más de 7 años de experiencia laboral acumulada en áreas técnicas, industriales y de sistemas de incendios. Ha desempeñado cargos de supervisión, mantenimiento y programación en proyectos con alta exigencia de seguridad para la industria minera, además de roles en logística y control de inventarios. Sus fortalezas incluyen liderazgo, trabajo bajo presión, y manejo de herramientas técnicas y software de diseño y programación. | AA12: Cuenta con al menos 4 años de experiencia directa en sistemas contra incendio, incluyendo supervisión, planificación, mantenimiento e instalación de sistemas automáticos y sensores inteligentes, manejo de normativas NFPA y programación de centrales NOTIFIER, específicamente en la División El Teniente de Codelco, lo que es altamente pertinente para cargos relacionados con sistemas contra incendio y automatización de seguridad. | AB12: Titulado de Ingeniero en Maquinaria, Vehículos Automotrices y Sistemas Electrónicos por INACAP Rancagua, además técnico de nivel superior en Mecánica Automotriz con especialización en sistemas electrónicos. Posee licencia de conducir categorías B-C y formación técnica complementaria relevante para el sector industrial y de mantenimiento eléctrico-electrónico.
A13: JUSTIN FRANCISCO ROJAS OLGUIN | B13: 18.041.874-1 | D13: jota.fcorojas@gmail.com | E13: 56942941117 | F13: Técnico Superior en Automatización y Control Industrial | G13: Jefe de área en sistemas contra incendio, Sercoing Ltda (Junio 2020 - a la fecha) | Supervisor, COASIN Rockwell Chile (Enero 2020 - Junio 2020) | Especialista eléctrico y de control, Magna IV Engineering (Febrero 2019 - Noviembre 2019) | Especialista capataz en sistema contra incendio, Sercoing Ltda (Noviembre 2018 - Febrero 2019) | Especialista en sistema contra incendio, Westfire Sudamerica Spa (Junio 2018 - Octubre 2018) | Supervisor, Jenergia Spa (Febrero 2016 - Junio 2018) | Instalador y programador telecomunicaciones, CS Tecnologia Spa (Abril 2015 - Enero 2016) | Técnico eléctrico, Edelectric Ingenieria Ltda (Abril 2014 - Marzo 2015) | Técnico eléctrico, Proyelec Ltda (Agosto 2012 - Marzo 2013) | H13: Excel nivel medio, AutoCAD nivel medio, NOTIFIER | I13: Sercoing Ltda | J13: Jefe de área en sistemas contra incendio | K13: Junio 2020 - a la fecha | M13: El candidato presenta una sólida formación técnica y una amplia experiencia de más de 12 años en áreas relevantes para cargos de supervisión y operación en automatización y sistemas contra incendio, con roles recientes de liderazgo. Su dominio de software es básico, pero adecuado para su especialidad. La progresión en su carrera es clara, destacando responsabilidades crecientes. Su CV es claro y detallado, aunque podría mejorar la presentación para facilitar la extracción de datos. | N13: 12 | O13: 3.5 | P13: 3.5 | Q13: 3.5 | R13: Supervisor de Sistemas de Automatización y Control Industrial | S13: 6.3 | V13: Ha desarrollado labores complementarias como instalador y programador de telecomunicaciones, montaje de torres para distribución de Internet en zonas rurales, mantenimiento electromecánico y trabajó en instalación y reparación de equipos de climatización industrial y residencial, aportando versatilidad y conocimiento en diversas áreas técnicas relacionadas. | Z13: Justin Francisco Rojas Olguin es un técnico superior con 12 años de experiencia en electricidad e instrumentación, especialmente en minería e industrias. Ha desempeñado funciones de montaje, mantenimiento, programación de tableros y sistemas automáticos contra incendio bajo normas NFPA, además de liderazgo como capataz y supervisor durante 6 años. Posee habilidades técnicas en lectura de planos, cableado, instalación de sistemas industriales y en control y automatización. | AA13: En los últimos años ha liderado y supervisado sistemas automáticos contra incendio en mineras importantes como CODELCO, realizando programación de centrales, sensores inteligentes y certificaciones bajo normativa NFPA, además de coordinar personal en terreno y efectuar capacitaciones en seguridad y sistemas contra incendios en salas eléctricas. También ha trabajado en proyectos de telecomunicaciones, control de acceso y seguridad electrónica relacionados con la automatización industrial. | AB13: Cuenta con título de Técnico Superior en Automatización y Control Industrial otorgado en 2016 con distinción. Actualmente cursa Ingeniería Industrial en Instituto Profesional IACC y ha realizado capacitaciones en sistemas de protección contra incendios FM-200, Novec 1230, y otros relacionados. Posee licencia de conducir clase B-C y formación técnica media en electricidad y electrónica.
A14: Miguel Angel Eduardo Mora Soto | D14: m.ms@live.cl | E14: 56975299371 | F14: Técnico en Mantenimiento Industrial | G14: Dic. 2008 – Nov. 2009 Compañia minera del pacífico (CMP) - Mantenedor mecánico planta | Nov. 2009 - Febrero 2020 WILUG - Trabajos de mantención y reparación en sistemas contra incendio, bombas impulsoras, mantenimiento de correas transportadoras y equipos de chancado en minera los pelambres | Mar. 2020 – Abr. 2022 Contitech (Continental chile) - null | Abr. 2022 – Sep. 2023 Thyssenkrupp chile - null | H14: Word, Power Point, Excel, Internet, Autocad | I14: Thyssenkrupp chile | K14: Abr. 2022 – Sep. 2023 | M14: El candidato cuenta con una sólida base técnica y extensa experiencia en mantenimiento industrial en minería, clave para el cargo. Su dominio de herramientas informáticas es básico, pero adecuado para la gestión en terreno. La progresión hacia cargos de supervisión es positiva, aunque el CV carece de claridad en algunos detalles actuales. Su formación técnica y experiencia práctica compensan limitaciones como la ausencia de título universitario. | N14: 14 | O14: 1.5 | P14: 0 | Q14: 12 | R14: Supervisor de mantenimiento industrial en minería | S14: 6.3 | V14: Experiencia adicional en conducción de vehículos en faenas mineras y trabajos en campaña, junto con cursos en trabajo en equipo, prevención de riesgos y metrología que aportan a un manejo integral de operaciones industriales. | Z14: Técnico en mantenimiento industrial con al menos 14 años de experiencia en el sector minero, especializado en mantenimiento predictivo, preventivo y correctivo de equipos industriales, sistemas contra incendio y correas transportadoras. Experiencia en plantas concentradoras y minas con énfasis en mantenimiento mecánico integral, complementada con habilidades en gestión y supervisión de turno. Destaca por su formación técnica y cursos adicionales en prevención de riesgos y sistemas hidráulicos. | AA14: Amplia experiencia en mantenimiento mecánico y supervisión en empresas mineras como minera los pelambres y CMP, realizando labores de mantenimiento en equipos de chancado, molinos, flotación, bombas y sistemas contra incendio, lo que demuestra habilidad en la operación y mantenimiento de sistemas críticos en minería. | AB14: Técnico nivel medio en Mecánica Industrial (2004-2008), Técnico nivel superior en Mantenimiento Mecánico Industrial (2016-2018), estudios incompletos en Ingeniería en Prevención de Riesgos. Posee cursos en primeros auxilios, conducción para minería en alta montaña, uso de sistemas contra incendio, trabajo en equipo, prevención de riesgos para minería, metrología, oleo hidráulica y sistemas de correas transportadoras.
